<?xml version='1.0'?>
<sdf version='1.5'>
  <model name="eduard-blue-mecanum">
    <static>false</static>
    <pose>0 0 0 0 0 0</pose>
      <!-- chassis -->
      <link name="chassis">
        <pose>0 0 0 0 0 0</pose>
        <inertial>
          <pose>0 0 0 0 0 0</pose>
          <mass>5.0</mass>
          <inertia>
            <ixx>9.885e-1</ixx>
            <iyy>2.099e0</iyy>
            <izz>1.317e0</izz>
            <ixy>-7.521e-4</ixy>
            <ixz>1.126e-3</ixz>
            <iyz>6.915e-3</iyz>
          </inertia>
        </inertial>
        <visual name="visual">
          <pose>0 0 0 0 0 1.570796327</pose>
          <geometry>
            <mesh>
              <uri>model://eduard_blue_mecanum/mesh/eduard-blue-chassis.dae</uri>
            </mesh>
          </geometry>
        </visual>
        <collision name="collision">
          <pose>0 0 0.06 0 0 0</pose>
          <geometry>
            <box>
              <size>0.34 0.22 0.12</size>
            </box>
          </geometry>
        </collision>
      </link>

      <!-- wheel rear right -->
      <link name="motor_a">
        <pose>-0.125 -0.18 0.02 -1.570796327 0 0</pose>
        <inertial>
          <pose>0 0 0 0 0 0</pose>
          <mass>0.3</mass>
          <inertia>
            <ixx>3.0e-5</ixx>
            <iyy>3.0e-5</iyy>
            <izz>5.0e-5</izz>
            <ixy>0</ixy>
            <ixz>0</ixz>
            <iyz>0</iyz>
          </inertia>
        </inertial>
        <visual name="visual">
          <geometry>
            <mesh>
              <uri>model://eduard_blue_mecanum/mesh/mecanum-wheel-left-eduard.dae</uri>
            </mesh>
          </geometry>
        </visual>
        <collision name="collision">
          <pose>0 0 0 0 0 0</pose>
          <geometry>
            <cylinder>
              <radius>0.05</radius>
              <length>0.055</length>
            </cylinder>
          </geometry>
          <max_contacts>10</max_contacts>
          <surface>
            <friction>
              <torsional>
                <coefficient>0.9</coefficient>
                <surface_radius>0.0865</surface_radius>
                <use_patch_radius>false</use_patch_radius>
                <ode>
                  <slip>0.02</slip>
                </ode>
              </torsional>
              <!-- <ode>
                <mu>0.45</mu>
                <mu2>0.45</mu2>
                <fdir1>1 1 1</fdir1>
                <slip1>0.02</slip1>
                <slip2>0.02</slip2>
              </ode> -->
            </friction>
            <contact>
              <ode>
                <min_depth>0.005</min_depth>
              </ode>
            </contact>
          </surface>          
        </collision>        
      </link> 

      <!-- wheel front right -->
      <link name="motor_b">
        <pose>0.125 -0.18 0.02 -1.570796327 0 0</pose>
        <inertial>
          <pose>0 0 0 0 0 0</pose>
          <mass>0.3</mass>
          <inertia>
            <ixx>3.0e-5</ixx>
            <iyy>3.0e-5</iyy>
            <izz>5.0e-5</izz>
            <ixy>0</ixy>
            <ixz>0</ixz>
            <iyz>0</iyz>
          </inertia>
        </inertial>
        <visual name="visual">
          <geometry>
            <mesh>
              <uri>model://eduard_blue_mecanum/mesh/mecanum-wheel-right-eduard.dae</uri>
            </mesh>
          </geometry>
        </visual>
        <collision name="collision">
          <pose>0 0 0 0 0 0</pose>
          <geometry>
            <cylinder>
              <radius>0.05</radius>
              <length>0.055</length>
            </cylinder>
          </geometry>
          <max_contacts>10</max_contacts>
          <surface>
            <friction>
              <torsional>
                <coefficient>0.9</coefficient>
                <surface_radius>0.0865</surface_radius>
                <use_patch_radius>false</use_patch_radius>
                <ode>
                  <slip>0.02</slip>
                </ode>
              </torsional>
              <!-- <ode>
                <mu>0.45</mu>
                <mu2>0.45</mu2>
                <fdir1>1 1 1</fdir1>
                <slip1>0.02</slip1>
                <slip2>0.02</slip2>
              </ode> -->
            </friction>
            <contact>
              <ode>
                <min_depth>0.005</min_depth>
              </ode>
            </contact>
          </surface>         
        </collision>        
      </link>

      <!-- wheel rear left -->
      <link name="motor_c">
        <pose>-0.125 0.18 0.02 1.570796327 0 0</pose>
        <inertial>
          <pose>0 0 0 0 0 0</pose>
          <mass>0.3</mass>
          <inertia>
            <ixx>3.0e-5</ixx>
            <iyy>3.0e-5</iyy>
            <izz>5.0e-5</izz>
            <ixy>0</ixy>
            <ixz>0</ixz>
            <iyz>0</iyz>
          </inertia>
        </inertial>
        <visual name="visual">
          <geometry>
            <mesh>
              <uri>model://eduard_blue_mecanum/mesh/mecanum-wheel-right-eduard.dae</uri>
            </mesh>
          </geometry>
        </visual>
        <collision name="collision">
          <pose>0 0 0 0 0 0</pose>
          <geometry>
            <cylinder>
              <radius>0.05</radius>
              <length>0.055</length>
            </cylinder>
          </geometry>
          <max_contacts>10</max_contacts>
          <surface>
            <friction>
              <torsional>
                <coefficient>0.9</coefficient>
                <surface_radius>0.0865</surface_radius>
                <use_patch_radius>false</use_patch_radius>
                <ode>
                  <slip>0.02</slip>
                </ode>
              </torsional>
              <!-- <ode>
                <mu>0.45</mu>
                <mu2>0.45</mu2>
                <fdir1>1 1 1</fdir1>
                <slip1>0.02</slip1>
                <slip2>0.02</slip2>
              </ode> -->
            </friction>
            <contact>
              <ode>
                <min_depth>0.005</min_depth>
              </ode>
            </contact>
          </surface>           
        </collision>        
      </link>

      <!-- wheel front left -->
      <link name="motor_d">
        <pose>0.125 0.18 0.02 1.570796327 0 0</pose>
        <inertial>
          <pose>0 0 0 0 0 0</pose>
          <mass>0.3</mass>
          <inertia>
            <ixx>3.0e-5</ixx>
            <iyy>3.0e-5</iyy>
            <izz>5.0e-5</izz>
            <ixy>0</ixy>
            <ixz>0</ixz>
            <iyz>0</iyz>
          </inertia>
        </inertial>
        <visual name="visual">
          <geometry>
            <mesh>
              <uri>model://eduard_blue_mecanum/mesh/mecanum-wheel-left-eduard.dae</uri>
            </mesh>
          </geometry>
        </visual>
        <collision name="collision">
          <pose>0 0 0 0 0 0</pose>
          <geometry>
            <cylinder>
              <radius>0.05</radius>
              <length>0.055</length>
            </cylinder>
          </geometry>
          <max_contacts>10</max_contacts>
          <surface>
            <friction>
              <torsional>
                <coefficient>0.9</coefficient>
                <surface_radius>0.0865</surface_radius>
                <use_patch_radius>false</use_patch_radius>
                <ode>
                  <slip>0.02</slip>
                </ode>
              </torsional>
              <!-- <ode>
                <mu>0.45</mu>
                <mu2>0.45</mu2>
                <fdir1>1 1 1</fdir1>
                <slip1>0.02</slip1>
                <slip2>0.02</slip2>
              </ode> -->
            </friction>
            <contact>
              <ode>
                <min_depth>0.005</min_depth>
              </ode>
            </contact>
          </surface>          
        </collision>        
      </link>

      <!-- Range Sensors -->
      <!-- Front Left-->
      <link name="range_front_left">
        <pose>0.17 0.063 0.045 0 0 0</pose>
        <inertial>
          <pose>0 0 0 0 0 0</pose>
          <mass>0.1</mass>
          <inertia>
            <ixx>3.0e-6</ixx>
            <iyy>3.0e-6</iyy>
            <izz>5.0e-6</izz>
            <ixy>0</ixy>
            <ixz>0</ixz>
            <iyz>0</iyz>
          </inertia>
        </inertial>             
        <sensor name="range/front/left" type="ray">
          <visualize>true</visualize>        
          <ray>
            <scan>
              <horizontal>
                <min_angle>-0.08726646</min_angle>
                <max_angle> 0.08726646</max_angle>
                <samples>4</samples>
              </horizontal>
              <vertical>
                <min_angle>-0.04363323</min_angle>
                <max_angle> 0.04363323</max_angle>
                <samples>2</samples>                
              </vertical>
            </scan>
            <range>
              <min>0.01</min>
              <max>2.0</max>
            </range>
            <noise>
              <type>gaussian</type>
              <stddev>0.0025</stddev>
            </noise>
          </ray>
        </sensor>
      </link>
      <!-- Front Right-->
      <link name="range_front_right">
        <pose>0.17 -0.063 0.045 0 0 0</pose>
        <inertial>
          <pose>0 0 0 0 0 0</pose>
          <mass>0.1</mass>
          <inertia>
            <ixx>3.0e-6</ixx>
            <iyy>3.0e-6</iyy>
            <izz>5.0e-6</izz>
            <ixy>0</ixy>
            <ixz>0</ixz>
            <iyz>0</iyz>
          </inertia>
        </inertial>             
        <sensor name="range/front/right" type="ray">
          <visualize>true</visualize>        
          <ray>
            <scan>
              <horizontal>
                <min_angle>-0.08726646</min_angle>
                <max_angle> 0.08726646</max_angle>
                <samples>4</samples>
              </horizontal>
              <vertical>
                <min_angle>-0.04363323</min_angle>
                <max_angle> 0.04363323</max_angle>
                <samples>2</samples>                
              </vertical>
            </scan>
            <range>
              <min>0.01</min>
              <max>2.0</max>
            </range>
            <noise>
              <type>gaussian</type>
              <stddev>0.0025</stddev>
            </noise>
          </ray>
        </sensor>
      </link>
      <!-- Rear Left -->
      <link name="range_rear_left">
        <pose>-0.17 0.063 0.05 0 0 3.141592654</pose>
        <inertial>
          <pose>0 0 0 0 0 0</pose>
          <mass>0.1</mass>
          <inertia>
            <ixx>3.0e-6</ixx>
            <iyy>3.0e-6</iyy>
            <izz>5.0e-6</izz>
            <ixy>0</ixy>
            <ixz>0</ixz>
            <iyz>0</iyz>
          </inertia>
        </inertial>             
        <sensor name="range/rear/left" type="ray">
          <visualize>true</visualize>
          <ray>
            <scan>
              <horizontal>
                <min_angle>-0.08726646</min_angle>
                <max_angle> 0.08726646</max_angle>
                <samples>4</samples>
              </horizontal>
              <vertical>
                <min_angle>-0.04363323</min_angle>
                <max_angle> 0.04363323</max_angle>
                <samples>2</samples>                
              </vertical>
            </scan>
            <range>
              <min>0.01</min>
              <max>2.0</max>
            </range>
            <noise>
              <type>gaussian</type>
              <stddev>0.0025</stddev>
            </noise>
          </ray>
        </sensor>
      </link>
      <!-- Rear Right-->
      <link name="range_rear_right">
        <pose>-0.17 -0.063 0.05 0 0 3.141592654</pose>
        <inertial>
          <pose>0 0 0 0 0 0</pose>
          <mass>0.1</mass>
          <inertia>
            <ixx>3.0e-6</ixx>
            <iyy>3.0e-6</iyy>
            <izz>5.0e-6</izz>
            <ixy>0</ixy>
            <ixz>0</ixz>
            <iyz>0</iyz>
          </inertia>
        </inertial>             
        <sensor name="range/rear/right" type="ray">
          <visualize>true</visualize>        
          <ray>
            <scan>
              <horizontal>
                <min_angle>-0.08726646</min_angle>
                <max_angle> 0.08726646</max_angle>
                <samples>4</samples>
              </horizontal>
              <vertical>
                <min_angle>-0.04363323</min_angle>
                <max_angle> 0.04363323</max_angle>
                <samples>2</samples>                
              </vertical>
            </scan>
            <range>
              <min>0.01</min>
              <max>2.0</max>
            </range>
            <noise>
              <type>gaussian</type>
              <stddev>0.0025</stddev>
            </noise>
          </ray>
        </sensor>
      </link>

      <!-- IMU Sensor -->
      <link name="imu">
        <pose>0 0 0 0 0 0</pose>
        <inertial>
          <pose>0 0 0 0 0 0</pose>
          <mass>0.1</mass>
          <inertia>
            <ixx>3.0e-6</ixx>
            <iyy>3.0e-6</iyy>
            <izz>5.0e-6</izz>
            <ixy>0</ixy>
            <ixz>0</ixz>
            <iyz>0</iyz>
          </inertia>
        </inertial>        
        <sensor name="imu" type="imu">
          <!-- <imu>
            <orientation_reference_frame>
              <localization>GRAV_DOWN</localization>
              <grav_dir_x parent_frame=chassis>
                0 0 1
              </grav_dir_x>
            </orientation_reference_frame>
          </imu> -->
        </sensor>
      </link>


      <!-- Joints. -->
      <joint type="revolute" name="axis_front_left">
        <pose>0 0 0 0 0 0</pose>
        <child>motor_d</child>
        <parent>chassis</parent>
        <axis>
          <xyz>0 0 1</xyz>
        </axis>
      </joint>
      <joint type="revolute" name="axis_front_right">
        <pose>0 0 0 0 0 0</pose>
        <child>motor_b</child>
        <parent>chassis</parent>
        <axis>
          <xyz>0 0 1</xyz>
        </axis>
      </joint>    
      <joint type="revolute" name="axis_rear_left">
        <pose>0 0 0 0 0 0</pose>
        <child>motor_c</child>
        <parent>chassis</parent>
        <axis>
          <xyz>0 0 1</xyz>
        </axis>
      </joint>    
      <joint type="revolute" name="axis_rear_right">
        <pose>0 0 0 0 0 0</pose>
        <child>motor_a</child>
        <parent>chassis</parent>
        <axis>
          <xyz>0 0 1</xyz>
        </axis>
      </joint>
      <joint type="fixed" name="mount_range_front_left">
        <child>range_front_left</child>
        <parent>chassis</parent>
      </joint>
      <joint type="fixed" name="mount_range_front_right">
        <child>range_front_right</child>
        <parent>chassis</parent>
      </joint>
      <joint type="fixed" name="mount_range_rear_left">
        <child>range_rear_left</child>
        <parent>chassis</parent>
      </joint>
      <joint type="fixed" name="mount_range_rear_right">
        <child>range_rear_right</child>
        <parent>chassis</parent>
      </joint>
      <joint type="fixed" name="mount_imu">
        <child>imu</child>
        <parent>chassis</parent>
      </joint>
            
      <!-- plugins to control robot behavior -->
     <plugin name="eduard_robot" filename="libeduard-model-plugin.so">
       <robot_namespace>/eduard/blue</robot_namespace>
     </plugin>
    </model>
</sdf>