<?xml version='1.0'?>
<sdf version='1.5'>
  <model name="eduard-offroad">
    <static>false</static>
    <pose>0 0 0 0 0 0</pose>
      <!-- chassis -->
      <link name="chassis">
        <pose>0 0 0 0 0 0</pose>
        <inertial>
          <pose>0 0 0.0 0 0 0</pose>
          <mass>5.0</mass>
          <inertia>
            <ixx>9.885e-1</ixx>
            <iyy>2.099e0</iyy>
            <izz>1.317e0</izz>
            <ixy>-7.521e-4</ixy>
            <ixz>1.126e-3</ixz>
            <iyz>6.915e-3</iyz>
          </inertia>
        </inertial>
        <visual name="visual">
          <geometry>
            <mesh>
              <uri>model://eduard_offroad/mesh/eduard-chassis.dae</uri>
            </mesh>
          </geometry>
        </visual>
        <collision name="collision">
          <pose>0 0 0.06 0 0 0</pose>
          <geometry>
            <box>
              <size>0.38 0.22 0.12</size>
            </box>
          </geometry>
        </collision>
      </link>

      <!-- wheel front left -->
      <link name="wheel_front_left">
        <pose>0.125 0.163 0.02 1.570796327 0 0</pose>
        <inertial>
          <pose>0 0 0 0 0 0</pose>
          <mass>0.3</mass>
          <inertia>
            <ixx>3.0e-5</ixx>
            <iyy>3.0e-5</iyy>
            <izz>5.0e-5</izz>
            <ixy>0</ixy>
            <ixz>0</ixz>
            <iyz>0</iyz>
          </inertia>
        </inertial>
        <visual name="visual">
          <geometry>
            <mesh>
              <uri>model://eduard_offroad/mesh/offroad-wheel-eduard.dae</uri>
            </mesh>
          </geometry>
        </visual>
        <collision name="collision">
          <pose>0 0 0 0 0 0</pose>
          <geometry>
            <cylinder>
              <radius>0.0865</radius>
              <length>0.081</length>
            </cylinder>
          </geometry>
          <max_contacts>10</max_contacts>
          <surface>
            <friction>
              <torsional>
                <coefficient>0.9</coefficient>
                <surface_radius>0.0865</surface_radius>
                <use_patch_radius>false</use_patch_radius>
                <ode>
                  <slip>0.02</slip>
                </ode>
              </torsional>
              <!-- <ode>
                <mu>0.45</mu>
                <mu2>0.45</mu2>
                <fdir1>1 1 1</fdir1>
                <slip1>0.02</slip1>
                <slip2>0.02</slip2>
              </ode> -->
            </friction>
            <contact>
              <ode>
                <min_depth>0.005</min_depth>
              </ode>
            </contact>
          </surface>          
        </collision>        
      </link>

      <!-- wheel front right -->
      <link name="wheel_front_right">
        <pose>0.125 -0.163 0.02 -1.570796327 0 0</pose>
        <inertial>
          <pose>0 0 0 0 0 0</pose>
          <mass>0.3</mass>
          <inertia>
            <ixx>3.0e-5</ixx>
            <iyy>3.0e-5</iyy>
            <izz>5.0e-5</izz>
            <ixy>0</ixy>
            <ixz>0</ixz>
            <iyz>0</iyz>
          </inertia>
        </inertial>
        <visual name="visual">
          <geometry>
            <mesh>
              <uri>model://eduard_offroad/mesh/offroad-wheel-eduard.dae</uri>
            </mesh>
          </geometry>
        </visual>
        <collision name="collision">
          <pose>0 0 0 0 0 0</pose>
          <geometry>
            <cylinder>
              <radius>0.0865</radius>
              <length>0.081</length>
            </cylinder>
          </geometry>
          <max_contacts>10</max_contacts>
          <surface>
            <friction>
              <torsional>
                <coefficient>0.9</coefficient>
                <surface_radius>0.0865</surface_radius>
                <use_patch_radius>false</use_patch_radius>
                <ode>
                  <slip>0.02</slip>
                </ode>
              </torsional>
              <!-- <ode>
                <mu>0.45</mu>
                <mu2>0.45</mu2>
                <fdir1>1 1 1</fdir1>
                <slip1>0.02</slip1>
                <slip2>0.02</slip2>
              </ode> -->
            </friction>
            <contact>
              <ode>
                <min_depth>0.005</min_depth>
              </ode>
            </contact>
          </surface>         
        </collision>        
      </link>

      <!-- wheel rear left -->
      <link name="wheel_rear_left">
        <pose>-0.125 0.163 0.02 1.570796327 0 0</pose>
        <inertial>
          <pose>0 0 0 0 0 0</pose>
          <mass>0.3</mass>
          <inertia>
            <ixx>3.0e-5</ixx>
            <iyy>3.0e-5</iyy>
            <izz>5.0e-5</izz>
            <ixy>0</ixy>
            <ixz>0</ixz>
            <iyz>0</iyz>
          </inertia>
        </inertial>
        <visual name="visual">
          <geometry>
            <mesh>
              <uri>model://eduard_offroad/mesh/offroad-wheel-eduard.dae</uri>
            </mesh>
          </geometry>
        </visual>
        <collision name="collision">
          <pose>0 0 0 0 0 0</pose>
          <geometry>
            <cylinder>
              <radius>0.0865</radius>
              <length>0.081</length>
            </cylinder>
          </geometry>
          <max_contacts>10</max_contacts>
          <surface>
            <friction>
              <torsional>
                <coefficient>0.9</coefficient>
                <surface_radius>0.0865</surface_radius>
                <use_patch_radius>false</use_patch_radius>
                <ode>
                  <slip>0.02</slip>
                </ode>
              </torsional>
              <!-- <ode>
                <mu>0.45</mu>
                <mu2>0.45</mu2>
                <fdir1>1 1 1</fdir1>
                <slip1>0.02</slip1>
                <slip2>0.02</slip2>
              </ode> -->
            </friction>
            <contact>
              <ode>
                <min_depth>0.005</min_depth>
              </ode>
            </contact>
          </surface>           
        </collision>        
      </link>

      <!-- wheel rear right -->
      <link name="wheel_rear_right">
        <pose>-0.125 -0.163 0.02 -1.570796327 0 0</pose>
        <inertial>
          <pose>0 0 0 0 0 0</pose>
          <mass>0.3</mass>
          <inertia>
            <ixx>3.0e-5</ixx>
            <iyy>3.0e-5</iyy>
            <izz>5.0e-5</izz>
            <ixy>0</ixy>
            <ixz>0</ixz>
            <iyz>0</iyz>
          </inertia>
        </inertial>
        <visual name="visual">
          <geometry>
            <mesh>
              <uri>model://eduard_offroad/mesh/offroad-wheel-eduard.dae</uri>
            </mesh>
          </geometry>
        </visual>
        <collision name="collision">
          <pose>0 0 0 0 0 0</pose>
          <geometry>
            <cylinder>
              <radius>0.0865</radius>
              <length>0.081</length>
            </cylinder>
          </geometry>
          <max_contacts>10</max_contacts>
          <surface>
            <friction>
              <torsional>
                <coefficient>0.9</coefficient>
                <surface_radius>0.0865</surface_radius>
                <use_patch_radius>false</use_patch_radius>
                <ode>
                  <slip>0.02</slip>
                </ode>
              </torsional>
              <!-- <ode>
                <mu>0.45</mu>
                <mu2>0.45</mu2>
                <fdir1>1 1 1</fdir1>
                <slip1>0.02</slip1>
                <slip2>0.02</slip2>
              </ode> -->
            </friction>
            <contact>
              <ode>
                <min_depth>0.005</min_depth>
              </ode>
            </contact>
          </surface>          
        </collision>        
      </link> 

      <!-- Add the laser range finder -->
      <link name="laser_link">
        <inertial>
          <!-- Mass of the laser range finder in kg -->
          <mass>0.1</mass>
        </inertial>
        <!-- Position is towards the front of the robot -->
        <!-- Laser finder is mounted on top -->
        <pose>0.10 0 0.139 0 0 -0.4</pose>
         
        <!-- Add a mesh to make it more visually appealing -->
        <visual name="visual">
          <geometry>
            <mesh>
              <uri>model://eduard_offroad/mesh/rplidar-a2.stl</uri>
            </mesh>
          </geometry>
        </visual>
         
        <!-- Collision properties of the base of the laser range finder-->
        <collision name="collision-base">
          <pose>0 0 -0.0145 0 0 0</pose>
          <geometry>
            <box>
              <size>0.05 0.05 0.041</size>
            </box>
          </geometry>
        </collision>
         
        <!-- Collision properties of the top of the laser range finder-->
        <collision name="collision-top">
          <pose>0 0 0.0205 0 0 0</pose>
          <geometry>
            <cylinder>
              <radius>0.021</radius>
              <length>0.029</length>
            </cylinder>
          </geometry>
        </collision>
         
<!-- Describes the type and properties of the sensor -->
	<sensor name="laser" type="ray">
	  <pose>0.01 0 0.0175 0 -0 0</pose>
          <ray>
            <scan>
              <horizontal>
                <samples>2000</samples>
                <resolution>1</resolution>
                <min_angle>-3.141592654</min_angle>
                <max_angle>3.141592654</max_angle>
              </horizontal>
            </scan>
            <range>
              <min>0.15</min>
              <max>12.0</max>
              <resolution>0.05</resolution>
            </range>
          </ray>
          <always_on>1</always_on>
          <update_rate>10</update_rate>
          <visualize>true</visualize>

          <plugin name='laser' filename='libgazebo_ros_ray_sensor.so'>
            <ros>
              <namespace>/demo</namespace>
              <argument>--ros-args --remap ~/out:=scan</argument>
            </ros>
            <output_type>sensor_msgs/LaserScan</output_type>
          </plugin>
	      </sensor>
      </link>

       <!-- Connect laser range finder to the robot's body -->
       <joint type="fixed" name="laser_joint">
         <child>laser_link</child>
         <parent>chassis</parent>
       </joint> 


      <!-- Joints. -->
      <joint type="revolute" name="axis_front_left">
        <pose>0 0 0 3.141592654 0 0</pose>
        <child>wheel_front_left</child>
        <parent>chassis</parent>
        <axis>
          <xyz>0 0 1</xyz>
        </axis>
      </joint>
      <joint type="revolute" name="axis_front_right">
        <pose>0 0 0 0 0 0</pose>
        <child>wheel_front_right</child>
        <parent>chassis</parent>
        <axis>
          <xyz>0 0 1</xyz>
        </axis>
      </joint>    
      <joint type="revolute" name="axis_rear_left">
        <pose>0 0 0 3.141592654 0 0</pose>
        <child>wheel_rear_left</child>
        <parent>chassis</parent>
        <axis>
          <xyz>0 0 1</xyz>
        </axis>
      </joint>    
      <joint type="revolute" name="axis_rear_right">
        <pose>0 0 0 0 0 0</pose>
        <child>wheel_rear_right</child>
        <parent>chassis</parent>
        <axis>
          <xyz>0 0 1</xyz>
        </axis>
      </joint>

      <!-- plugins to control robot behavior -->
      <plugin name='skid_steer_drive' filename='libgazebo_ros_diff_drive.so'>
        <!-- <ros> -->
          <!-- Set namespace -->
          <!-- <namespace>/demo</namespace> -->

          <!-- Remap default topics -->
          <!-- <remapping>cmd_vel:=cmd_demo</remapping> -->
          <!-- <remapping>odom:=odom_demo</remapping> -->
        <!-- </ros> -->

        <!-- Update rate -->
        <update_rate>20</update_rate>

        <!-- Number of wheel pairs -->
        <num_wheel_pairs>2</num_wheel_pairs>

        <!-- wheels0 -->
        <left_joint>axis_front_left</left_joint>
        <right_joint>axis_front_right</right_joint>

        <!-- wheels1-->
        <left_joint>axis_rear_left</left_joint>
        <right_joint>axis_rear_right</right_joint>

        <!-- kinematics -->
        <wheel_separation>0.326</wheel_separation>
        <wheel_separation>0.326</wheel_separation>

        <wheel_diameter>0.173</wheel_diameter>
        <wheel_diameter>0.173</wheel_diameter>

        <!-- limits -->
        <max_wheel_torque>20</max_wheel_torque>
        <max_wheel_acceleration>1.0</max_wheel_acceleration>

        <!-- output -->
        <publish_odom>true</publish_odom>
        <publish_odom_tf>true</publish_odom_tf>
        <publish_wheel_tf>true</publish_wheel_tf>

        <odometry_frame>odom</odometry_frame>
        <robot_base_frame>base_frame</robot_base_frame>
      </plugin>    
    </model>
</sdf>
